Workbook
Name IQ_CH: 110000
Name IQ_CQ: 5000
Name IQ_CY: 10000
Name IQ_DAILY: 500000
Name IQ_FH: 100000
Name IQ_FQ: 500
Name IQ_FY: 1000
Name IQ_LTM: 2000
Name IQ_MONTH: 15000
Name IQ_NTM: 6000
Name IQ_WEEK: 50000
Name IQ_YTD: 3000

Sheet Legend
B2: Colour Code
B3: Green = Historical Number
B4: Black = Formulas/links to another sheet
B5: Blue = Hardcoded numbers
B6: Highlighted Blue = Manual input/assumptions
B7: Highlighted in Yellow = Unsure, highlighted part might contain bugs that needs to be addressed

Sheet CORE MODEL>>>

Sheet Summary
A1: =Input!A1 -> Name | B1: =Input!B1 -> ABM Industries Inc
A2: =Input!A2 -> Ticker | B2: =Input!B2 -> ABM
A3: =Input!A3 -> Currency | B3: =Input!B3 -> USD
A4: =Input!A4 -> Last Full FY | B4: =Input!B4 -> 2025
A5: =Input!A5 -> Last Edit: | B5: =Input!B5 -> 46156
D7: USD | F7: FX Rate | H7: =B3 -> USD | J7: ="Blended TP ("&B3&")" -> Blended TP (USD) | L7: =H16*F16+H18*F18+H20*F20 -> 69.946744
B8: =B2 -> ABM | D8: =H8/F8 -> 40.2 | F8: 1 | H8: 40.2 | J8: Price Upside | L8: =L7/H8-1 -> 0.73996876
B9: FS Shares Outstanding (MM) | D9: =DCF!H50 -> 61.2 | H9: =D9 -> 61.2 | J9: 3Y Dividend Yield | L9: =SUM(Model!H43:I43)/Summary!H8 -> 0.047214628
B10: Market Cap (MM) | D10: =D9*D8 -> 2460.24 | H10: =H9*H8 -> 2460.24 | J10: Total Return | L10: =SUM(L8:L9) -> 0.78718339
B11: (+) Debt | D11: =H11/$F$8 -> 1693.4 | H11: =DCF!C57 -> 1693.4
B12: (+) Minority Interest | D12: =H12/$F$8 -> 0 | H12: =DCF!C58 -> 0
B13: (-) Cash | D13: =H13/$F$8 -> 104.1 | H13: =DCF!C59 -> 104.1 | J13: Scenario Toggle | L13: 2 | M13: <- 1: Bull, 2: Base, 3: Bear
B14: Enterprise Value | D14: =D10+D11+D12-D13 -> 4049.54 | H14: =H10+H11+H12-H13 -> 4049.54
F15: Weight
B16: DCF TP (Exit Multiple) | D16: =H16/$F$8 -> 75.844278 | F16: 0.3 | H16: =DCF!D60 -> 75.844278
B17: Upside/Downside | D17: =H17 -> 0.88667358 | H17: =DCF!D62 -> 0.88667358
B18: DCF TP (Terminal Growth) | D18: =H18/$F$8 -> 67.766832 | F18: 0.3 | H18: =DCF!D70 -> 67.766832
B19: Upside/Downside | D19: =H19 -> 0.68574208 | H19: =DCF!D72 -> 0.68574208
B20: Comps | D20: =H20/$F$8 -> 67.158528 | F20: =1-F18-F16 -> 0.4 | H20: =Comps!N33 -> 67.158528
B21: Upside/Downside | D21: =H21 -> 0.67061016 | H21: =H20/H8-1 -> 0.67061016
B23: =DCF!B17 -> In Millions of USD | H23: =DCF!C17 -> FY2021 | I23: =DCF!D17 -> FY2022 | J23: =DCF!E17 -> FY2023 | K23: =DCF!F17 -> FY2024 | L23: =DCF!G17 -> FY2025 | M23: =DCF!H17 -> FY2026 E | N23: =DCF!I17 -> FY2027 E | O23: =DCF!J17 -> FY2028 E | ... V23: =DCF!Q17 -> FY2035 E
B24: =DCF!B18 -> Revenue | H24: =DCF!C18 -> 6372.8 | I24: =DCF!D18 -> 7806.6 | J24: =DCF!E18 -> 8096.4 | K24: =DCF!F18 -> 8359.4 | L24: =DCF!G18 -> 8745.9 | M24: =DCF!H18 -> 9287.821 | N24: =DCF!I18 -> 9742.0359 | O24: =DCF!J18 -> 10178.13 | ... V24: =DCF!Q18 -> 13452.234
B25: =DCF!B19 -> Revenue Growth | H25: =DCF!C19 -> 0 | I25: =DCF!D19 -> 0.22498745 | J25: =DCF!E19 -> 0.037122435 | K25: =DCF!F19 -> 0.032483573 | L25: =DCF!G19 -> 0.046235376 | M25: =DCF!H19 -> 0.061962863 | N25: =DCF!I19 -> 0.048904352 | O25: =DCF!J19 -> 0.044764218 | ... V25: =DCF!Q19 -> 0.031281151
B26: =DCF!B20 -> Segment Operating Expenses | H26: =DCF!C20 -> 5788.4 | I26: =DCF!D20 -> 7169.7 | J26: =DCF!E20 -> 7456.2 | K26: =DCF!F20 -> 7702.3 | L26: =DCF!G20 -> 8058.2 | M26: =DCF!H20 -> 8549.9289 | N26: =DCF!I20 -> 8941.7987 | O26: =DCF!J20 -> 9312.3273 | ... V26: =DCF!Q20 -> 12278.027
B27: =DCF!B21 -> Segment Operating Expenses as a % of Revenue | H27: =DCF!C21 -> 0.90829777 | I27: =DCF!D21 -> 0.91841519 | J27: =DCF!E21 -> 0.92092782 | K27: =DCF!F21 -> 0.92139388 | L27: =DCF!G21 -> 0.92136887 | M27: =DCF!H21 -> 0.92055272 | N27: =DCF!I21 -> 0.9178573 | O27: =DCF!J21 -> 0.91493495 | ... V27: =DCF!Q21 -> 0.91271284
B28: =DCF!B22 -> Total Segment Operating profit | H28: =DCF!C22 -> 584.4 | I28: =DCF!D22 -> 636.9 | J28: =DCF!E22 -> 640.2 | K28: =DCF!F22 -> 657.1 | L28: =DCF!G22 -> 687.7 | M28: =DCF!H22 -> 737.89209 | N28: =DCF!I22 -> 800.23718 | O28: =DCF!J22 -> 865.80316 | ... V28: =DCF!Q22 -> 1174.2073
B29: =DCF!B23 -> Margin | H29: =DCF!C23 -> 0.091702234 | I29: =DCF!D23 -> 0.081584813 | J29: =DCF!E23 -> 0.07907218 | K29: =DCF!F23 -> 0.07860612 | L29: =DCF!G23 -> 0.07863113 | M29: =DCF!H23 -> 0.079447278 | N29: =DCF!I23 -> 0.082142705 | O29: =DCF!J23 -> 0.085065048 | ... V29: =DCF!Q23 -> 0.087287155
B30: =DCF!B24 -> EBIT | H30: =DCF!C24 -> 209.8 | I30: =DCF!D24 -> 352.4 | J30: =DCF!E24 -> 409.4 | K30: =DCF!F24 -> 213 | L30: =DCF!G24 -> 311.8 | M30: =DCF!H24 -> 314.59926 | N30: =DCF!I24 -> 364.87574 | O30: =DCF!J24 -> 418.39794 | ... V30: =DCF!Q24 -> 603.31184
B31: =DCF!B25 -> EBIT Margin | H31: =DCF!C25 -> 0.032921165 | I31: =DCF!D25 -> 0.045141291 | J31: =DCF!E25 -> 0.050565684 | K31: =DCF!F25 -> 0.025480298 | L31: =DCF!G25 -> 0.035650991 | M31: =DCF!H25 -> 0.033872235 | N31: =DCF!I25 -> 0.037453746 | O31: =DCF!J25 -> 0.041107543 | ... V31: =DCF!Q25 -> 0.044848449
B32: =DCF!B26 -> EBITDA | H32: =DCF!C26 -> 299.7 | I32: =DCF!D26 -> 464.8 | J32: =DCF!E26 -> 530.1 | K32: =DCF!F26 -> 319.6 | L32: =DCF!G26 -> 417.4 | M32: =DCF!H26 -> 420.85926 | N32: =DCF!I26 -> 468.41148 | O32: =DCF!J26 -> 519.36307 | ... V32: =DCF!Q26 -> 717.37286
B33: =DCF!B27 -> EBITDA Margin | H33: =DCF!C27 -> 0.047027994 | I33: =DCF!D27 -> 0.059539364 | J33: =DCF!E27 -> 0.065473544 | K33: =DCF!F27 -> 0.038232409 | L33: =DCF!G27 -> 0.04772522 | M33: =DCF!H27 -> 0.045313024 | N33: =DCF!I27 -> 0.048081477 | O33: =DCF!J27 -> 0.051027355 | ... V33: =DCF!Q27 -> 0.053327414
B34: =DCF!B28 -> Tax | H34: =DCF!C28 -> -53.5 | I34: =DCF!D28 -> -79.6 | J34: =DCF!E28 -> -79.8 | K34: =DCF!F28 -> -52.2 | L34: =DCF!G28 -> -57.5 | M34: =DCF!H28 -> -57.076064 | N34: =DCF!I28 -> -68.220852 | O34: =DCF!J28 -> -82.694409 | ... V34: =DCF!Q28 -> -134.72135
B35: =DCF!B29 -> NOPAT | H35: =DCF!C29 -> 156.3 | I35: =DCF!D29 -> 272.8 | J35: =DCF!E29 -> 329.6 | K35: =DCF!F29 -> 160.8 | L35: =DCF!G29 -> 254.3 | M35: =DCF!H29 -> 257.52319 | N35: =DCF!I29 -> 296.65489 | O35: =DCF!J29 -> 335.70353 | ... V35: =DCF!Q29 -> 468.59049
B36: =DCF!B35 -> FCFF | H36: =DCF!C35 -> -341.9 | I36: =DCF!D35 -> -133 | J36: =DCF!E35 -> 93.3 | K36: =DCF!F35 -> 5.3 | L36: =DCF!G35 -> 247.1 | M36: =DCF!H35 -> 14.268224 | N36: =DCF!I35 -> 263.08539 | O36: =DCF!J35 -> 298.96705 | ... V36: =DCF!Q35 -> 427.26288

Sheet Input
A1: Name | B1: ABM Industries Inc
A2: Ticker | B2: ABM
A3: Currency | B3: USD
A4: Last Full FY | B4: 2025
A5: Last Edit: | B5: =TODAY() -> 46156
C7: ="In Millions of " & B3 -> In Millions of USD | E7: FY | F7: ="FY"&F8 -> FY2021 | G7: ="FY"&G8 -> FY2022 | H7: ="FY"&H8 -> FY2023 | I7: ="FY"&I8 -> FY2024 | J7: ="FY"&J8 -> FY2025 | K7: ="FY"&K8&" E" -> FY2026 E | L7: ="FY"&L8&" E" -> FY2027 E | M7: ="FY"&M8&" E" -> FY2028 E | N7: ="FY"&N8&" E" -> FY2029 E | O7: ="FY"&O8&" E" -> FY2030 E | P7: ="FY"&P8&" E" -> FY2031 E | Q7: ="FY"&Q8&" E" -> FY2032 E | R7: ="FY"&R8&" E" -> FY2033 E | ... T7: ="FY"&T8&" E" -> FY2035 E
F8: =$J$8+F9 -> 2021 | G8: =$J$8+G9 -> 2022 | H8: =$J$8+H9 -> 2023 | I8: =$J$8+I9 -> 2024 | J8: =B4 -> 2025 | K8: =K9+$J$8 -> 2026 | L8: =L9+$J$8 -> 2027 | M8: =M9+$J$8 -> 2028 | N8: =N9+$J$8 -> 2029 | O8: =O9+$J$8 -> 2030 | P8: =P9+$J$8 -> 2031 | Q8: =Q9+$J$8 -> 2032 | R8: =R9+$J$8 -> 2033 | ... T8: =T9+$J$8 -> 2035
F9: =G9-1 -> -4 | G9: =H9-1 -> -3 | H9: =I9-1 -> -2 | I9: =J9-1 -> -1 | J9: 0 | K9: =J9+1 -> 1 | L9: =K9+1 -> 2 | M9: =L9+1 -> 3 | N9: =M9+1 -> 4 | O9: =N9+1 -> 5 | P9: =O9+1 -> 6 | Q9: =P9+1 -> 7 | R9: =Q9+1 -> 8 | ... T9: =S9+1 -> 10
K10: =(K14-TODAY())/K15 -> #VALUE! | L10: =(L14-TODAY())/L15 -> #VALUE! | M10: =(M14-TODAY())/M15 -> #VALUE! | N10: =(N14-TODAY())/N15 -> #VALUE! | O10: =(O14-TODAY())/O15 -> #VALUE! | P10: =(P14-TODAY())/P15 -> #VALUE! | Q10: =(Q14-TODAY())/Q15 -> #VALUE! | R10: =(R14-TODAY())/R15 -> #VALUE! | ... T10: =(T14-TODAY())/T15 -> #VALUE!
E11: FY | F11: =F9&$E$11 -> -4FY | G11: =G9&$E$11 -> -3FY | H11: =H9&$E$11 -> -2FY | I11: =I9&$E$11 -> -1FY | J11: =J9&$E$11 -> 0FY | K11: =K9&$E$11 -> 1FY | L11: =L9&$E$11 -> 2FY | M11: =M9&$E$11 -> 3FY | ... T11: =T9&$E$11 -> 10FY
E12: A | F12: =F9&$E$12 -> -4A | G12: =G9&$E$12 -> -3A | H12: =H9&$E$12 -> -2A | I12: =I9&$E$12 -> -1A | J12: =J9&$E$12 -> 0A | K12: =K9&$E$12 -> 1A | L12: =L9&$E$12 -> 2A | M12: =M9&$E$12 -> 3A | ... T12: =T9&$E$12 -> 10A
E13: Period Start | F13: ="12/31/"&F8-1 -> 12/31/2020 | G13: ="12/31/"&G8-1 -> 12/31/2021 | H13: ="12/31/"&H8-1 -> 12/31/2022 | I13: ="12/31/"&I8-1 -> 12/31/2023 | J13: ="12/31/"&J8-1 -> 12/31/2024 | K13: ="12/31/"&K8-1 -> 12/31/2025 | L13: ="12/31/"&L8-1 -> 12/31/2026 | M13: ="12/31/"&M8-1 -> 12/31/2027 | ... T13: ="12/31/"&T8-1 -> 12/31/2034
E14: Period End | F14: ="12/31/"&F8 -> 12/31/2021 | G14: ="12/31/"&G8 -> 12/31/2022 | H14: ="12/31/"&H8 -> 12/31/2023 | I14: ="12/31/"&I8 -> 12/31/2024 | J14: ="12/31/"&J8 -> 12/31/2025 | K14: ="12/31/"&K8 -> 12/31/2026 | L14: ="12/31/"&L8 -> 12/31/2027 | M14: ="12/31/"&M8 -> 12/31/2028 | ... T14: ="12/31/"&T8 -> 12/31/2035
E15: Days in Period | F15: 365 | G15: 365 | H15: 365 | I15: 366 | J15: 365 | K15: 365 | L15: 365 | M15: 366 | N15: 365 | O15: 365 | P15: 365 | Q15: 366 | R15: 365 | S15: 365 | T15: 365
C17: Income Statement
C19: Revenue | F19: =Model!C9 -> 6372.8 | G19: =Model!D9 -> 7806.6 | H19: =Model!E9 -> 8096.4 | I19: =Model!F9 -> 8359.4 | J19: =Model!G9 -> 8745.9 | K19: =Model!H9 -> 9287.821 | L19: =Model!I9 -> 9742.0359 | M19: =Model!J9 -> 10178.13 | ... T19: =Model!Q9 -> 13452.234
C20: Revenue Growth | G20: =G19/F19-1 -> 0.22498745 | H20: =H19/G19-1 -> 0.037122435 | I20: =I19/H19-1 -> 0.032483573 | J20: =J19/I19-1 -> 0.046235376 | K20: =K19/J19-1 -> 0.061962863 | L20: =L19/K19-1 -> 0.048904352 | M20: =M19/L19-1 -> 0.044764218 | N20: =N19/M19-1 -> 0.057542579 | ... T20: =T19/S19-1 -> 0.031281151
C22: =Model!B10 -> Segment Operating Expenses | F22: =Model!C10 -> 5788.4 | G22: =Model!D10 -> 7169.7 | H22: =Model!E10 -> 7456.2 | I22: =Model!F10 -> 7702.3 | J22: =Model!G10 -> 8058.2 | K22: =Model!H10 -> 8549.9289 | L22: =Model!I10 -> 8941.7987 | M22: =Model!J10 -> 9312.3273 | ... T22: =Model!Q10 -> 12278.027
C23: =Model!B50 -> Operating Expense growth | G23: =G22/F22-1 -> 0.23863244 | H23: =H22/G22-1 -> 0.039959831 | I23: =I22/H22-1 -> 0.033006089 | J23: =J22/I22-1 -> 0.046206977 | K23: =K22/J22-1 -> 0.061022177 | L23: =L22/K22-1 -> 0.045833105 | M23: =M22/L22-1 -> 0.041437819 | N23: =N22/M22-1 -> 0.057777278 | ... T23: =T22/S22-1 -> 0.031093885
C24: =Model!B55 -> Operating Margin | F24: =1-F22/F19 -> 0.091702234 | G24: =1-G22/G19 -> 0.081584813 | H24: =1-H22/H19 -> 0.07907218 | I24: =1-I22/I19 -> 0.07860612 | J24: =1-J22/J19 -> 0.07863113 | K24: =K22/K19 -> 0.92055272 | L24: =L22/L19 -> 0.9178573 | M24: =M22/M19 -> 0.91493495 | N24: =N22/N19 -> 0.915138 | O24: =O22/O19 -> 0.91402235 | P24: =P22/P19 -> 0.91394939 | Q24: =Q22/Q19 -> 0.91343841 | R24: =R22/R19 -> 0.91330414 | ... T24: =T22/T19 -> 0.91271284
C26: =Model!B13 -> Corporate expense (unallocated) | F26: =Model!C13 -> -374.6 | G26: =Model!D13 -> -284.5 | H26: =Model!E13 -> -226.6 | I26: =Model!F13 -> -433.1 | J26: =Model!G13 -> -370.5 | K26: =K27*K$19 -> -371.51284 | L26: =L27*L$19 -> -389.68143 | M26: =M27*M$19 -> -407.12522 | N26: =N27*N$19 -> -430.55225 | O26: =O27*O$19 -> -447.06419 | P26: =P27*P$19 -> -462.52522 | Q26: =Q27*Q$19 -> -486.24021 | R26: =R27*R$19 -> -500.44783 | ... T26: =T27*T$19 -> -538.08937
C27: As % of revenue | F27: =F26/F$19 -> -0.05878107 | G27: =G26/G$19 -> -0.036443522 | H27: =H26/H$19 -> -0.027987748 | I27: =I26/I$19 -> -0.051809939 | J27: =J26/J$19 -> -0.042362707 | K27: -0.04 | L27: -0.04 | M27: -0.04 | N27: -0.04 | O27: -0.04 | P27: -0.04 | Q27: -0.04 | R27: -0.04 | S27: -0.04 | T27: -0.04
C29: Total amortization | K29: =K30+K67 -> 51.78 | L29: =L30+L67 -> 45.68 | M29: =M30+M67 -> 40.28 | N29: =N30+N67 -> 38.98 | O29: =O30+O67 -> 33.88 | P29: =P30+P67 -> 31.42 | Q29: =Q30+Q67 -> 34.206 | R29: =R30+R67 -> 32.2134 | ... T29: =T30+T67 -> 32.806054
C30: Amortization of pre-existing Intangible Assets | F30: =Model!C143 -> 45 | G30: =Model!D143 -> 72.1 | H30: =Model!E143 -> 76.5 | I30: =Model!F143 -> 56.1 | J30: =Model!G143 -> 52.5 | K30: 46.5 | L30: 40.4 | M30: 35 | N30: 29.7 | O30: 24.6 | P30: =O30+O30*P31 -> 22.14 | Q30: =P30+P30*Q31 -> 19.926 | R30: =Q30+Q30*R31 -> 17.9334 | S30: =R30+R30*S31 -> 16.14006 | T30: =S30+S30*T31 -> 14.526054 | U30: <- first 5 years using management guidance
C31: Amortization % change | G31: =(G30-F30)/F30 -> 0.60222222 | H31: =(H30-G30)/G30 -> 0.061026352 | I31: =(I30-H30)/H30 -> -0.26666667 | J31: =(J30-I30)/I30 -> -0.064171123 | K31: =(K30-J30)/J30 -> -0.11428571 | L31: =(L30-K30)/K30 -> -0.1311828 | M31: =(M30-L30)/L30 -> -0.13366337 | N31: =(N30-M30)/M30 -> -0.15142857 | O31: =(O30-N30)/N30 -> -0.17171717 | P31: -0.1 | Q31: -0.1 | R31: -0.1 | S31: -0.1 | T31: -0.1 | U31: <- assumed 10% afterwards
C32: Income from JV and Associates | F32: =Model!C22 -> 2.1 | G32: =Model!D22 -> 2.4 | H32: =Model!E22 -> 3.9 | I32: =Model!F22 -> 6.5 | J32: =Model!G22 -> 4.6 | K32: 0 | L32: 0 | M32: 0 | N32: 0 | O32: 0 | P32: 0 | Q32: 0 | R32: 0 | S32: 0 | T32: 0
C33: Others | F33: =Model!C23 -> 0 | G33: =Model!D23 -> 0 | H33: =Model!E23 -> 0 | I33: =Model!F23 -> 0 | J33: =Model!G23 -> 0 | K33: 0 | L33: 0 | M33: 0 | N33: 0 | O33: 0 | P33: 0 | Q33: 0 | R33: 0 | S33: 0 | T33: 0
C34: Non-Controlling Interests | F34: {=Model!C27:G27} -> 0 | G34: 0 | H34: 0 | I34: 0 | J34: 0 | K34: 0 | L34: 0 | M34: 0 | N34: 0 | O34: 0 | P34: 0 | Q34: 0 | R34: 0 | S34: 0 | T34: 0
C35: Effective Tax Rate | F35: =Model!C29 -> 0.29187125 | G35: =Model!D29 -> 0.25374562 | H35: =Model!E29 -> 0.24108761 | I35: =Model!F29 -> 0.38810409 | J35: =Model!G29 -> 0.26136364 | K35: 0.25 | L35: =K35 -> 0.25 | M35: =L35 -> 0.25 | N35: =M35 -> 0.25 | O35: =N35 -> 0.25 | P35: =O35 -> 0.25 | Q35: =P35 -> 0.25 | R35: =Q35 -> 0.25 | S35: =R35 -> 0.25 | T35: =S35 -> 0.25
C36: Nominal Tax Rate | F36: =Model!C30 -> 0.2 | G36: =Model!D30 -> 0.2 | H36: =Model!E30 -> 0.2 | I36: =Model!F30 -> 0.2 | J36: =Model!G30 -> 0.2 | K36: 0.2 | L36: 0.2 | M36: 0.2 | N36: 0.2 | O36: 0.2 | P36: 0.2 | Q36: 0.2 | R36: 0.2 | S36: 0.2 | T36: 0.2
C38: Other Model Inputs
C39: Capex / Sales | F39: =Model!C155/Model!C9 -> -0.0053822496 | G39: =Model!D155/Model!D9 -> -0.0065073143 | H39: =Model!E155/Model!E9 -> -0.0064967146 | I39: =Model!F155/Model!F9 -> -0.0071057731 | J39: =Model!G155/Model!G9 -> -0.0090671057 | K39: -0.007 | L39: -0.007 | M39: -0.007 | N39: -0.007 | O39: -0.007 | P39: -0.007 | Q39: -0.007 | R39: -0.007 | S39: -0.007 | T39: -0.007
C40: Depreciation as a % of fixed assets | G40: =Model!D142/Model!C71 -> 0.16904362 | H40: =Model!E142/Model!D71 -> 0.1837074 | I40: =Model!F142/Model!E71 -> 0.20620661 | J40: =Model!G142/Model!F71 -> 0.21079794 | K40: 0.2 | L40: 0.2 | M40: 0.2 | N40: 0.2 | O40: 0.2 | P40: 0.2 | Q40: 0.2 | R40: 0.2 | S40: 0.2 | T40: 0.2
C41: Depreciation as a % of revenue | F41: =Model!C142/F19 -> 0.0070455687 | G41: =Model!D142/G19 -> 0.0051622986 | H41: =Model!E142/H19 -> 0.0054592164 | I41: =Model!F142/I19 -> 0.0060411034 | J41: =Model!G142/J19 -> 0.0060714163 | K41: =Model!H142/K19 -> 0.0058657461 | L41: =Model!I142/L19 -> 0.0059387727 | M41: =Model!J142/M19 -> 0.0059623066 | ... T41: =Model!Q142/T19 -> 0.0060402583
C42: SBC % of Revenue | F42: =Model!C38/Model!C9 -> -0.005256716 | G42: =Model!D38/Model!D9 -> -0.0039069505 | H42: =Model!E38/Model!E9 -> -0.0037671064 | I42: =Model!F38/Model!F9 -> -0.0035887743 | J42: =Model!G38/Model!G9 -> -0.004344893 | K42: -0.0035 | L42: -0.0035 | M42: -0.0035 | N42: -0.0035 | O42: -0.0035 | P42: -0.0035 | Q42: -0.0035 | R42: -0.0035 | S42: -0.0035 | T42: -0.0035
C43: Cost of Debt | F43: =Model!C21/Model!C199 -> -0.02763285 | G43: =Model!D21/Model!D199 -> -0.029111772 | H43: =Model!E21/Model!E199 -> -0.056493685 | I43: =Model!F21/Model!F199 -> -0.057748488 | J43: =Model!G21/Model!G199 -> -0.056926893 | K43: -0.055 | L43: -0.055 | M43: -0.055 | N43: -0.055 | O43: -0.055 | P43: -0.055 | Q43: -0.055 | R43: -0.055 | S43: -0.055 | T43: -0.055
C44: Deferred Revenue / Total Revenue | F44: =Model!C87/Model!C9 -> 0 | G44: =Model!D87/Model!D9 -> 0 | H44: =Model!E87/Model!E9 -> 0.011128403 | I44: =Model!F87/Model!F9 -> 0.0076201641 | J44: =Model!G87/Model!G9 -> 0.008541145 | K44: 0.01 | L44: =K44 -> 0.01 | M44: =L44 -> 0.01 | N44: =M44 -> 0.01 | O44: =N44 -> 0.01 | P44: =O44 -> 0.01 | Q44: =P44 -> 0.01 | R44: =Q44 -> 0.01 | S44: =R44 -> 0.01 | T44: =S44 -> 0.01
C45: Restructuring | F45: =Model!C16 -> 0 | G45: =Model!D16 -> 0 | H45: =Model!E16 -> 0 | I45: =Model!F16 -> 0 | J45: =Model!G16 -> -13.4 | K45: 0 | L45: 0 | M45: 0 | N45: 0 | O45: 0 | P45: 0 | Q45: 0 | R45: 0 | S45: 0 | T45: 0
C47: Working Capital
C48: Accounts receivable % of revenue | G48: =Model!D67/Model!D9 -> 0.1637973 | H48: =Model!E67/Model!E9 -> 0.16859345 | I48: =Model!F67/Model!F9 -> 0.16557408 | J48: =Model!G67/Model!G9 -> 0.16820453 | K48: 0.165 | L48: =K48 -> 0.165 | M48: =L48 -> 0.165 | N48: =M48 -> 0.165 | O48: =N48 -> 0.165 | P48: =O48 -> 0.165 | Q48: =P48 -> 0.165 | R48: =Q48 -> 0.165 | S48: =R48 -> 0.165 | T48: =S48 -> 0.165
...

Sheet Model
A5: =Input!$A$5 -> Last Edit: | B5: =Input!$B$5 -> 46156
B6: =Input!C7 -> In Millions of USD | C6: =Segments!D5 -> FY2021 | D6: =Segments!E5 -> FY2022 | E6: =Segments!F5 -> FY2023 | F6: =Segments!G5 -> FY2024 | G6: =Segments!H5 -> FY2025 | H6: =Segments!I5 -> FY2026 E | I6: =Segments!J5 -> FY2027 E | J6: =Segments!K5 -> FY2028 E | ... Q6: =Segments!R5 -> FY2035 E
B8: Consolidated Statement of Income
B9: Revenue | C9: =Segments!D13 -> 6372.8 | D9: =Segments!E13 -> 7806.6 | E9: =Segments!F13 -> 8096.4 | F9: =Segments!G13 -> 8359.4 | G9: =Segments!H13 -> 8745.9 | H9: =Segments!I13 -> 9287.821 | I9: =Segments!J13 -> 9742.0359 | J9: =Segments!K13 -> 10178.13 | ... Q9: =Segments!R13 -> 13452.234
B10: Segment Operating Expenses | C10: =C9-C11 -> 5788.4 | D10: =D9-D11 -> 7169.7 | E10: =E9-E11 -> 7456.2 | F10: =F9-F11 -> 7702.3 | G10: =G9-G11 -> 8058.2 | H10: =H9-H11 -> 8549.9289 | I10: =I9-I11 -> 8941.7987 | J10: =J9-J11 -> 9312.3273 | ... Q10: =Q9-Q11 -> 12278.027
B11: Total Segment Operating profit | C11: =Segments!D41 -> 584.4 | D11: =Segments!E41 -> 636.9 | E11: =Segments!F41 -> 640.2 | F11: =Segments!G41 -> 657.1 | G11: =Segments!H41 -> 687.7 | H11: =Segments!I41 -> 737.8921 | I11: =Segments!J41 -> 800.23718 | J11: =Segments!K41 -> 865.80316 | ... Q11: =Segments!R41 -> 1174.2073
B13: Corporate expense (unallocated) | C13: -374.6 | D13: -284.5 | E13: -226.6 | F13: -433.1 | G13: -370.5 | H13: =Input!K26 -> -371.51284 | I13: =Input!L26 -> -389.68143 | J13: =Input!M26 -> -407.12522 | K13: =Input!N26 -> -430.55225 | L13: =Input!O26 -> -447.06419 | M13: =Input!P26 -> -462.52522 | N13: =Input!Q26 -> -486.24021 | O13: =Input!R26 -> -500.44783 | ... Q13: =Input!T26 -> -538.08937
B14: Adjustments | E14: -4.2 | F14: -11 | G14: -5.4
B15: Amortization | C15: -67.3 | D15: -55.3 | E15: -76.5 | F15: -56.1 | G15: -52.5 | H15: =-Input!K29 -> -51.78 | I15: =-Input!L29 -> -45.68 | J15: =-Input!M29 -> -40.28 | K15: =-Input!N29 -> -38.98 | L15: =-Input!O29 -> -33.88 | M15: =-Input!P29 -> -31.42 | N15: =-Input!Q29 -> -34.206 | O15: =-Input!R29 -> -32.2134 | ... Q15: =-Input!T29 -> -32.806054
B16: Restructuring | C16: 0 | D16: 0 | E16: 0 | F16: 0 | G16: -13.4 | H16: =Input!K45 -> 0 | I16: =Input!L45 -> 0 | J16: =Input!M45 -> 0 | K16: =Input!N45 -> 0 | L16: =Input!O45 -> 0 | M16: =Input!P45 -> 0 | N16: =Input!Q45 -> 0 | O16: =Input!R45 -> 0 | ... Q16: =Input!T45 -> 0
B17: Total Other Costs | C17: =C13+C14 -> -374.6 | D17: =D13+D14 -> -284.5 | E17: =E13+E14 -> -230.8 | F17: =F13+F14 -> -444.1 | G17: =G13+G14 -> -375.9 | H17: =SUM(H13:H16) -> -423.29284 | I17: =SUM(I13:I16) -> -435.36143 | J17: =SUM(J13:J16) -> -447.40522 | K17: =SUM(K13:K16) -> -469.53225 | L17: =SUM(L13:L16) -> -480.94419 | M17: =SUM(M13:M16) -> -493.94522 | N17: =SUM(N13:N16) -> -520.44621 | O17: =SUM(O13:O16) -> -532.66123 | ... Q17: =SUM(Q13:Q16) -> -570.89542
B19: Operating Income (EBIT) | C19: =C11+C17 -> 209.8 | D19: =D11+D17 -> 352.4 | E19: =E11+E17 -> 409.4 | F19: =F11+F17 -> 213 | G19: =G11+G17 -> 311.8 | H19: =H11+H17 -> 314.59926 | I19: =I11+I17 -> 364.87574 | J19: =J11+J17 -> 418.39794 | ... Q19: =Q11+Q17 -> 603.31184
B21: Interest expense | C21: -28.6 | D21: -41.1 | E21: -82.3 | F21: -85 | G21: -96.4 | H21: =Input!K107 -> -86.295 | I21: =Input!L107 -> -91.992332 | J21: =Input!M107 -> -87.620304 | K21: =Input!N107 -> -83.474712 | L21: =Input!O107 -> -86.693908 | M21: =Input!P107 -> -79.778539 | N21: =Input!Q107 -> -72.435201 | O21: =Input!R107 -> -75.12224 | ... Q21: =Input!T107 -> -64.426447
B22: Income from JV and Associates | C22: 2.1 | D22: 2.4 | E22: 3.9 | F22: 6.5 | G22: 4.6 | H22: =Input!K32 -> 0 | I22: =Input!L32 -> 0 | J22: =Input!M32 -> 0 | K22: =Input!N32 -> 0 | L22: =Input!O32 -> 0 | M22: =Input!P32 -> 0 | N22: =Input!Q32 -> 0 | O22: =Input!R32 -> 0 | ... Q22: =Input!T32 -> 0
B23: Others | C23: 0 | D23: 0 | E23: 0 | F23: 0 | G23: 0 | H23: =Input!K33 -> 0 | I23: =Input!L33 -> 0 | J23: =Input!M33 -> 0 | K23: =Input!N33 -> 0 | L23: =Input!O33 -> 0 | M23: =Input!P33 -> 0 | N23: =Input!Q33 -> 0 | O23: =Input!R33 -> 0 | ... Q23: =Input!T33 -> 0
B25: Pre-tax Income | C25: =C19+SUM(C21:C23) -> 183.3 | D25: =D19+SUM(D21:D23) -> 313.7 | E25: =E19+SUM(E21:E23) -> 331 | F25: =F19+SUM(F21:F23) -> 134.5 | G25: =G19+SUM(G21:G23) -> 220 | H25: =H19+SUM(H21:H23) -> 228.30426 | I25: =I19+SUM(I21:I23) -> 272.88341 | J25: =J19+SUM(J21:J23) -> 330.77764 | ... Q25: =Q19+SUM(Q21:Q23) -> 538.88539
B26: Income Tax Expense | C26: -53.5 | D26: -79.6 | E26: -79.8 | F26: -52.2 | G26: -57.5 | H26: =-H25*H29 -> -57.076064 | I26: =-I25*I29 -> -68.220852 | J26: =-J25*J29 -> -82.694409 | K26: =-K25*K29 -> -90.107787 | L26: =-L25*L29 -> -98.325021 | M26: =-M25*M29 -> -105.32267 | N26: =-N25*N29 -> -114.84044 | O26: =-O25*O29 -> -119.22135 | ... Q26: =-Q25*Q29 -> -134.72135
B27: NCI | C27: 0 | D27: 0 | E27: 0 | F27: 0 | G27: 0 | H27: =Input!K34 -> 0 | I27: =Input!L34 -> 0 | J27: =Input!M34 -> 0 | K27: =Input!N34 -> 0 | L27: =Input!O34 -> 0 | M27: =Input!P34 -> 0 | N27: =Input!Q34 -> 0 | O27: =Input!R34 -> 0 | ... Q27: =Input!T34 -> 0
B28: Net Income | C28: =C25+C26+C27 -> 129.8 | D28: =D25+D26+D27 -> 234.1 | E28: =E25+E26+E27 -> 251.2 | F28: =F25+F26+F27 -> 82.3 | G28: =G25+G26+G27 -> 162.5 | H28: =H25+H26+H27 -> 171.22819 | I28: =I25+I26+I27 -> 204.66256 | J28: =J25+J26+J27 -> 248.08323 | ... Q28: =Q25+Q26+Q27 -> 404.16404
B29: Effective Tax Rate | C29: =-C26/C25 -> 0.29187125 | D29: =-D26/D25 -> 0.25374562 | E29: =-E26/E25 -> 0.24108761 | F29: =-F26/F25 -> 0.38810409 | G29: =-G26/G25 -> 0.26136364 | H29: =Input!K35 -> 0.25 | I29: =Input!L35 -> 0.25 | J29: =Input!M35 -> 0.25 | K29: =Input!N35 -> 0.25 | L29: =Input!O35 -> 0.25 | M29: =Input!P35 -> 0.25 | N29: =Input!Q35 -> 0.25 | O29: =Input!R35 -> 0.25 | ... Q29: =Input!T35 -> 0.25
B30: Nominal Tax Rate | C30: 0.2 | D30: 0.2 | E30: 0.2 | F30: 0.2 | G30: 0.2 | H30: =Input!K36 -> 0.2 | I30: =Input!L36 -> 0.2 | J30: =Input!M36 -> 0.2 | K30: =Input!N36 -> 0.2 | L30: =Input!O36 -> 0.2 | M30: =Input!P36 -> 0.2 | N30: =Input!Q36 -> 0.2 | O30: =Input!R36 -> 0.2 | ... Q30: =Input!T36 -> 0.2
B32: FCF Build
B33: D&A | C33: =C144 -> 89.9 | D33: =D144 -> 112.4 | E33: =E144 -> 120.7 | F33: =F144 -> 106.6 | G33: =G144 -> 105.6 | H33: =H144 -> 106.26 | I33: =I144 -> 103.53574 | J33: =J144 -> 100.96513 | ... Q33: =Q144 -> 114.06102
B34: EBITDA | C34: =C19+C144 -> 299.7 | D34: =D19+D144 -> 464.8 | E34: =E19+E144 -> 530.1 | F34: =F19+F144 -> 319.6 | G34: =G19+G144 -> 417.4 | H34: =H19+H144 -> 420.85926 | I34: =I19+I144 -> 468.41148 | J34: =J19+J144 -> 519.36307 | ... Q34: =Q19+Q144 -> 717.37286
B35: Capex | C35: =C155 -> -34.3 | D35: =D155 -> -50.8 | E35: =E155 -> -52.6 | F35: =F155 -> -59.4 | G35: =G155 -> -79.3 | H35: =H155 -> -65.014747 | I35: =I155 -> -68.194251 | J35: =J155 -> -71.246913 | ... Q35: =Q155 -> -94.165639
B36: Change in NWC | C36: =C147 -> 156.3 | D36: =D147 -> -272.8 | E36: =E147 -> -304.4 | F36: =F147 -> -88.4 | G36: =G147 -> 3.2 | H36: =H147 -> -20.500221 | I36: =I147 -> -68.910983 | J36: =J147 -> -66.454703 | ... Q36: =Q147 -> -61.222997
B37: FCFF (OCF - Capex) | C37: =C152+C155 -> 283.5 | D37: =D152+D155 -> -0.6 | E37: =E152+E155 -> 35 | F37: =F152+F155 -> 170.5 | G37: =G152+G155 -> 200.5 | H37: =H152+H155 -> 224.4806 | I37: =I152+I155 -> 205.19018 | J37: =J152+J155 -> 246.9702 | ... Q37: =Q152+Q155 -> 409.91925
B38: Stock based comp | C38: -33.5 | D38: -30.5 | E38: -30.5 | F38: -30 | G38: -38 | H38: =H9*Input!K42 -> -32.507373 | I38: =I9*Input!L42 -> -34.097126 | J38: =J9*Input!M42 -> -35.623457 | K38: =K9*Input!N42 -> -37.673322 | L38: =L9*Input!O42 -> -39.118117 | M38: =M9*Input!P42 -> -40.470957 | N38: =N9*Input!Q42 -> -42.546018 | O38: =O9*Input!R42 -> -43.789186 | ... Q38: =Q9*Input!T42 -> -47.08282
B39: Per share
B40: GAAP EPS - Basic | C40: =C28/C201 -> 1.925816 | D40: =D28/D201 -> 3.4888227 | E40: =E28/E201 -> 3.8060606 | F40: =F28/F201 -> 1.3022152 | G40: =G28/G201 -> 2.6083467 | H40: =H28/H201 -> 2.8162531 | I40: =I28/I201 -> 3.510507 | J40: =J28/J201 -> 4.445936 | ... Q40: =Q28/Q201 -> 9.5547055
B41: GAAP EPS - Diluted | C41: =C28/C202 -> 1.9088235 | D41: =D28/D202 -> 3.4681481 | E41: =E28/E202 -> 3.7888386 | F41: =F28/F202 -> 1.2940252 | G41: =G28/G202 -> 2.5917065 | H41: =H28/H202 -> 2.7978463 | I41: =I28/I202 -> 3.4865853 | J41: =J28/J202 -> 4.4142923 | ... Q41: =Q28/Q202 -> 9.4652
B42: Net Cash | C42: =(C64+C65-C89)/C201 -> -18.145401 | D42: =(D64+D65-D89)/D201 -> -19.078987 | E42: =(E64+E65-E89)/E201 -> -15.290909 | F42: =(F64+F65-F89)/F201 -> -17.748418 | G42: =(G64+G65-G89)/G201 -> -16.17817 | H42: =(H64+H65-H89)/H201 -> -17.490321 | I42: =(I64+I65-I89)/I201 -> -18.650923 | J42: =(J64+J65-J89)/J201 -> -19.893159 | ... Q42: =(Q64+Q65-Q89)/Q201 -> -31.089894
B43: Dividend per share (Basic) | C43: 0.76 | D43: 0.78 | E43: 0.88 | F43: 0.9 | G43: 1.06 | H43: =-Input!K88/Model!H201 -> 0.84487594 | I43: =-Input!L88/Model!I201 -> 1.0531521 | J43: =-Input!M88/Model!J201 -> 1.7783744 | K43: =-Input!N88/Model!K201 -> 1.7424158 | L43: =-Input!O88/Model!L201 -> 1.7083498 | M43: =-Input!P88/Model!M201 -> 1.9227261 | N43: =-Input!Q88/Model!N201 -> 2.1622677 | O43: =-Input!R88/Model!O201 -> 2.3427776 | ... Q43: =-Input!T88/Model!Q201 -> 2.8664116
B44: Consensus
B45: # of estimates
B46: BBG Best Revenue
B47: v.s. Consensus
B48: Growth Matrix & Margins
B49: Revenue growth | D49: =D9/C9-1 -> 0.22498745 | E49: =E9/D9-1 -> 0.037122435 | F49: =F9/E9-1 -> 0.032483573 | G49: =G9/F9-1 -> 0.046235376 | H49: =H9/G9-1 -> 0.061962863 | I49: =I9/H9-1 -> 0.048904352 | J49: =J9/I9-1 -> 0.044764218 | K49: =K9/J9-1 -> 0.057542579 | ... Q49: =Q9/P9-1 -> 0.031281151
B50: Operating Expense growth | D50: =D10/C10-1 -> 0.23863244 | E50: =E10/D10-1 -> 0.039959831 | F50: =F10/E10-1 -> 0.033006089 | G50: =G10/F10-1 -> 0.046206977 | H50: =H10/G10-1 -> 0.061022177 | I50: =I10/H10-1 -> 0.045833105 | J50: =J10/I10-1 -> 0.041437819 | K50: =K10/J10-1 -> 0.057777278 | ... Q50: =Q10/P10-1 -> 0.031093885
...

Sheet Segments
A1: =Input!$A$5 -> Last Edit: | C1: =Input!$B$5 -> 46156
C4: =Input!C7 -> In Millions of USD
C5: Revenue | D5: =Input!F7 -> FY2021 | E5: =Input!G7 -> FY2022 | F5: =Input!H7 -> FY2023 | G5: =Input!I7 -> FY2024 | H5: =Input!J7 -> FY2025 | I5: =Input!K7 -> FY2026 E | J5: =Input!L7 -> FY2027 E | K5: =Input!M7 -> FY2028 E | ... R5: =Input!T7 -> FY2035 E
C6: Revenue Breakdown
C7: Business & Industry | D7: 3346.5 | E7: 4095.9 | F7: 4089.4 | G7: 4059.2 | H7: 4126 | I7: =H7*(1+I17) -> 4208.52 | J7: =I7*(1+J17) -> 4292.6904 | K7: =J7*(1+K17) -> 4357.0808 | L7: =K7*(1+L17) -> 4422.437 | M7: =L7*(1+M17) -> 4466.6613 | N7: =M7*(1+N17) -> 4511.328 | O7: =N7*(1+O17) -> 4556.4412 | P7: =O7*(1+P17) -> 4602.0056 | ... R7: =Q7*(1+R17) -> 4694.506
C8: Manufacturing & Distribution | D8: 987.1 | E8: 1445.2 | F8: 1526.7 | G8: 1554.3 | H8: 1618.6 | I8: =H8*(1+I18) -> 1683.344 | J8: =I8*(1+J18) -> 1750.6778 | K8: =J8*(1+K18) -> 1820.7049 | L8: =K8*(1+L18) -> 1875.326 | M8: =L8*(1+M18) -> 1931.5858 | N8: =M8*(1+N18) -> 1989.5334 | O8: =N8*(1+O18) -> 2049.2194 | P8: =O8*(1+P18) -> 2090.2038 | ... R8: =Q8*(1+R18) -> 2174.648
C9: Education | D9: 836.4 | E9: 834.7 | F9: 880.4 | G9: 904.1 | H9: 922 | I9: =H9*(1+I19) -> 940.44 | J9: =I9*(1+J19) -> 959.2488 | K9: =J9*(1+K19) -> 978.43378 | L9: =K9*(1+L19) -> 998.00245 | M9: =L9*(1+M19) -> 1017.9625 | N9: =M9*(1+N19) -> 1038.3218 | O9: =N9*(1+O19) -> 1059.0882 | P9: =O9*(1+P19) -> 1080.2699 | ... R9: =Q9*(1+R19) -> 1123.9129
C10: Aviation | D10: 668.8 | E10: 804 | F10: 925.7 | G10: 1032.6 | H10: 1118.7 | I10: =H10*(1+I20) -> 1197.009 | J10: =I10*(1+J20) -> 1280.7996 | K10: =J10*(1+K20) -> 1357.6476 | L10: =K10*(1+L20) -> 1439.1065 | M10: =L10*(1+M20) -> 1511.0618 | N10: =M10*(1+N20) -> 1586.6149 | O10: =N10*(1+O20) -> 1650.0795 | P10: =O10*(1+P20) -> 1699.5819 | ... R10: =Q10*(1+R20) -> 1803.0864
C11: Technical Solutions | D11: 534 | E11: 626.8 | F11: 674.2 | G11: 809.2 | H11: 960.6 | I11: =H11*(1+I21) -> 1133.508 | J11: =I11*(1+J21) -> 1314.8693 | K11: =J11*(1+K21) -> 1498.951 | L11: =K11*(1+L21) -> 1678.8251 | M11: =L11*(1+M21) -> 1846.7076 | N11: =M11*(1+N21) -> 1994.4442 | O11: =N11*(1+O21) -> 2153.9998 | P11: =O11*(1+P21) -> 2283.2397 | ... R11: =Q11*(1+R21) -> 2565.4482
C12: Additional non-organic revenue from acquisitions | I12: =H12*(1+I22)+'Acquisition related'!E10 -> 125 | J12: =I12*(1+J22)+'Acquisition related'!F10 -> 143.75 | K12: =J12*(1+K22)+'Acquisition related'!G10 -> 165.3125 | L12: =K12*(1+L22)+'Acquisition related'!H10 -> 350.10938 | M12: =L12*(1+M22)+'Acquisition related'!I10 -> 402.62578 | N12: =M12*(1+N22)+'Acquisition related'!J10 -> 442.88836 | O12: =N12*(1+O22)+'Acquisition related'!K10 -> 687.1772 | P12: =O12*(1+P22)+'Acquisition related'!L10 -> 755.89491 | ... R12: =Q12*(1+R22)+'Acquisition related'!N10 -> 1090.6328
C13: Total Revenue | D13: =SUM(D7:D11) -> 6372.8 | E13: =SUM(E7:E11) -> 7806.6 | F13: =SUM(F7:F11) -> 8096.4 | G13: =SUM(G7:G11) -> 8359.4 | H13: =SUM(H7:H11) -> 8745.9 | I13: =SUM(I7:I12) -> 9287.821 | J13: =SUM(J7:J12) -> 9742.0359 | K13: =SUM(K7:K12) -> 10178.13 | L13: =SUM(L7:L12) -> 10763.806 | M13: =SUM(M7:M12) -> 11176.605 | N13: =SUM(N7:N12) -> 11563.131 | O13: =SUM(O7:O12) -> 12156.005 | P13: =SUM(P7:P12) -> 12511.196 | ... R13: =SUM(R7:R12) -> 13452.234
C16: YoY Growth
C17: =C7 -> Business & Industry | E17: =E7/D7-1 -> 0.22393545 | F17: =F7/E7-1 -> -0.0015869528 | G17: =G7/F7-1 -> -0.0073849464 | H17: =H7/G7-1 -> 0.016456445 | I17: 0.02 | J17: =I17 -> 0.02 | K17: 0.015 | L17: =K17 -> 0.015 | M17: 0.01 | N17: =M17 -> 0.01 | O17: =N17 -> 0.01 | P17: =O17 -> 0.01 | Q17: =P17 -> 0.01 | R17: =Q17 -> 0.01
C18: =C8 -> Manufacturing & Distribution | E18: =E8/D8-1 -> 0.46408672 | F18: =F8/E8-1 -> 0.056393579 | G18: =G8/F8-1 -> 0.018078208 | H18: =H8/G8-1 -> 0.041369105 | I18: 0.04 | J18: 0.04 | K18: 0.04 | L18: 0.03 | M18: 0.03 | N18: 0.03 | O18: 0.03 | P18: 0.02 | Q18: 0.02 | R18: 0.02
C19: =C9 -> Education | E19: =E9/D9-1 -> -0.0020325203 | F19: =F9/E9-1 -> 0.05475021 | G19: =G9/F9-1 -> 0.026919582 | H19: =H9/G9-1 -> 0.019798695 | I19: 0.02 | J19: 0.02 | K19: 0.02 | L19: 0.02 | M19: 0.02 | N19: 0.02 | O19: 0.02 | P19: 0.02 | Q19: 0.02 | R19: 0.02
C20: =C10 -> Aviation | E20: =E10/D10-1 -> 0.20215311 | F20: =F10/E10-1 -> 0.15136816 | G20: =G10/F10-1 -> 0.11548018 | H20: =H10/G10-1 -> 0.083381755 | I20: 0.07 | J20: 0.07 | K20: 0.06 | L20: 0.06 | M20: 0.05 | N20: 0.05 | O20: 0.04 | P20: 0.03 | Q20: 0.03 | R20: 0.03
C21: =C11 -> Technical Solutions | E21: =E11/D11-1 -> 0.17378277 | F21: =F11/E11-1 -> 0.075622208 | G21: =G11/F11-1 -> 0.20023732 | H21: =H11/G11-1 -> 0.18709837 | I21: =I55 -> 0.18 | J21: =J55 -> 0.16 | K21: =K55 -> 0.14 | L21: =L55 -> 0.12 | M21: =M55 -> 0.1 | N21: =N55 -> 0.08 | O21: =O55 -> 0.08 | P21: =P55 -> 0.06 | ... R21: =R55 -> 0.06
C22: Acquired companies' growth | I22: 0.15 | J22: =I22 -> 0.15 | K22: =J22 -> 0.15 | L22: =K22 -> 0.15 | M22: =L22 -> 0.15 | N22: 0.1 | O22: =N22 -> 0.1 | P22: =O22 -> 0.1 | Q22: =P22 -> 0.1 | R22: =Q22 -> 0.1
C23: Total Revenue Growth | E23: =E13/D13-1 -> 0.22498745 | F23: =F13/E13-1 -> 0.037122435 | G23: =G13/F13-1 -> 0.032483573 | H23: =H13/G13-1 -> 0.046235376 | I23: =I13/H13-1 -> 0.061962863 | J23: =J13/I13-1 -> 0.048904352 | K23: =K13/J13-1 -> 0.044764218 | L23: =L13/K13-1 -> 0.057542579 | ... R23: =R13/Q13-1 -> 0.031281151
C25: Revenue Mix
C26: =C17 -> Business & Industry | D26: =D7/D$13 -> 0.5251224 | E26: =E7/E$13 -> 0.52467143 | F26: =F7/F$13 -> 0.50508868 | G26: =G7/G$13 -> 0.48558509 | H26: =H7/SUM(H$7:H$11) -> 0.47176391 | I26: =I7/SUM(I$7:I$11) -> 0.45930396 | J26: =J7/SUM(J$7:J$11) -> 0.44723511 | K26: =K7/SUM(K$7:K$11) -> 0.4351503 | L26: =L7/SUM(L$7:L$11) -> 0.42467502 | M26: =M7/SUM(M$7:M$11) -> 0.41457862 | N26: =N7/SUM(N$7:N$11) -> 0.40568612 | O26: =O7/SUM(O$7:O$11) -> 0.39728918 | ... R26: =R7/SUM(R$7:R$11) -> 0.3797652
C27: =C18 -> Manufacturing & Distribution | D27: =D8/D$13 -> 0.15489267 | E27: =E8/E$13 -> 0.18512541 | F27: =F8/F$13 -> 0.18856529 | G27: =G8/G$13 -> 0.1859344 | H27: =H8/SUM(H$7:H$11) -> 0.18506958 | I27: =I8/SUM(I$7:I$11) -> 0.1837146 | J27: =J8/SUM(J$7:J$11) -> 0.18239483 | K27: =K8/SUM(K$7:K$11) -> 0.18183741 | L27: =L8/SUM(L$7:L$11) -> 0.18008264 | M27: =M8/SUM(M$7:M$11) -> 0.17928249 | N27: =N8/SUM(N$7:N$11) -> 0.17891098 | O27: =O8/SUM(O$7:O$11) -> 0.17867731 | ... R27: =R8/SUM(R$7:R$11) -> 0.1759196
C28: =C19 -> Education | D28: =D9/D$13 -> 0.13124529 | E28: =E9/E$13 -> 0.10692235 | F28: =F9/F$13 -> 0.10873969 | G28: =G9/G$13 -> 0.1081537 | H28: =H9/SUM(H$7:H$11) -> 0.10542083 | I28: =I9/SUM(I$7:I$11) -> 0.10263651 | J28: =J9/SUM(J$7:J$11) -> 0.099939595 | K28: =K9/SUM(K$7:K$11) -> 0.097718123 | L28: =L9/SUM(L$7:L$11) -> 0.095835557 | M28: =M9/SUM(M$7:M$11) -> 0.094483431 | N28: =N9/SUM(N$7:N$11) -> 0.093372225 | O28: =O9/SUM(O$7:O$11) -> 0.092344936 | ... R28: =R9/SUM(R$7:R$11) -> 0.090919681
C29: =C20 -> Aviation | D29: =D10/D$13 -> 0.10494602 | E29: =E10/E$13 -> 0.10298978 | F29: =F10/F$13 -> 0.11433477 | G29: =G10/G$13 -> 0.12352561 | H29: =H10/SUM(H$7:H$11) -> 0.12791136 | I29: =I10/SUM(I$7:I$11) -> 0.13063761 | J29: =J10/SUM(J$7:J$11) -> 0.13344045 | K29: =K10/SUM(K$7:K$11) -> 0.13559096 | L29: =L10/SUM(L$7:L$11) -> 0.13819362 | M29: =M10/SUM(M$7:M$11) -> 0.14025104 | N29: =N10/SUM(N$7:N$11) -> 0.14267809 | O29: =O10/SUM(O$7:O$11) -> 0.14387516 | ... R29: =R10/SUM(R$7:R$11) -> 0.14586188
C30: =C21 -> Technical Solutions | D30: =D11/D$13 -> 0.083793623 | E30: =E11/E$13 -> 0.080291036 | F30: =F11/F$13 -> 0.083271577 | G30: =G11/G$13 -> 0.096801206 | H30: =H11/SUM(H$7:H$11) -> 0.10983432 | I30: =I11/SUM(I$7:I$11) -> 0.12370732 | J30: =J11/SUM(J$7:J$11) -> 0.13699001 | K30: =K11/SUM(K$7:K$11) -> 0.14970321 | L30: =L11/SUM(L$7:L$11) -> 0.16121317 | M30: =M11/SUM(M$7:M$11) -> 0.17140442 | N30: =N11/SUM(N$7:N$11) -> 0.17935259 | O30: =O11/SUM(O$7:O$11) -> 0.18781341 | ... R30: =R11/SUM(R$7:R$11) -> 0.20753364
C31: Total | D31: =SUM(D26:D30) -> 1 | E31: =SUM(E26:E30) -> 1 | F31: =SUM(F26:F30) -> 1 | G31: =SUM(G26:G30) -> 1 | H31: =SUM(H26:H30) -> 1 | I31: =SUM(I26:I30) -> 1 | J31: =SUM(J26:J30) -> 1 | K31: =SUM(K26:K30) -> 1 | ... R31: =SUM(R26:R30) -> 1
C33: EBIT | D33: =D5 -> FY2021 | E33: =E5 -> FY2022 | F33: =F5 -> FY2023 | G33: =G5 -> FY2024 | H33: =H5 -> FY2025 | I33: =I5 -> FY2026 E | J33: =J5 -> FY2027 E | K33: =K5 -> FY2028 E | ... R33: =R5 -> FY2035 E
C34: EBIT Breakdown
C35: Business & Industry | D35: 337.8 | E35: 334.9 | F35: 315.6 | G35: 307 | H35: 316.9 | I35: =I44*I7 -> 332.47308 | J35: =J44*J7 -> 343.41523 | K35: =K44*K7 -> 352.92354 | L35: =L44*L7 -> 362.63983 | M35: =M44*M7 -> 368.49956 | N35: =N44*N7 -> 372.18456 | O35: =O44*O7 -> 375.9064 | P35: =P44*P7 -> 379.66547 | ... R35: =R44*R7 -> 387.29674
C36: Manufacturing & Distribution | D36: 103.8 | E36: 161.8 | F36: 161.7 | G36: 166.3 | H36: 151.4 | I36: =I45*I8 -> 159.91768 | J36: =J45*J8 -> 170.69108 | K36: =K45*K8 -> 182.07049 | L36: =L45*L8 -> 192.22092 | M36: =M45*M8 -> 197.98754 | N36: =N45*N8 -> 203.92717 | O36: =O45*O8 -> 210.04499 | P36: =P45*P8 -> 214.24589 | ... R36: =R45*R8 -> 222.90142
C37: Education | D37: 60.5 | E37: 47.1 | F37: 49.7 | G37: 55.3 | H37: 67.7 | I37: =I46*I9 -> 75.2352 | J37: =J46*J9 -> 81.536148 | K37: =K46*K9 -> 88.05904 | L37: =L46*L9 -> 89.820221 | M37: =M46*M9 -> 91.616625 | N37: =N46*N9 -> 93.448958 | O37: =O46*O9 -> 95.317937 | P37: =P46*P9 -> 97.224295 | ... R37: =R46*R9 -> 101.15216
C38: Aviation | D38: 32.5 | E38: 29.3 | F38: 60 | G38: 59.1 | H38: 65.2 | I38: =I47*I10 -> 65.835495 | J38: =J47*J10 -> 70.44398 | K38: =K47*K10 -> 74.670618 | L38: =L47*L10 -> 79.150856 | M38: =M47*M10 -> 83.108398 | N38: =N47*N10 -> 87.263818 | O38: =O47*O10 -> 90.754371 | P38: =P47*P10 -> 93.477002 | ... R38: =R47*R10 -> 99.169752
C39: Technical Solutions | D39: 49.8 | E39: 63.8 | F39: 53.2 | G39: 69.4 | H39: 86.5 | I39: =I48*I11 -> 90.68064 | J39: =J48*J11 -> 118.33824 | K39: =K48*K11 -> 149.8951 | L39: =L48*L11 -> 151.09426 | M39: =M48*M11 -> 175.43722 | N39: =N48*N11 -> 189.4722 | O39: =O48*O11 -> 204.62998 | P39: =P48*P11 -> 216.90778 | ... R39: =R48*R11 -> 243.71758
C40: Additional non-organic EBIT from acquisitions | I40: =I49*I12 -> 13.75 | J40: =J49*J12 -> 15.8125 | K40: =K49*K12 -> 18.184375 | L40: =L49*L12 -> 38.512031 | M40: =M49*M12 -> 44.288836 | N40: =N49*N12 -> 48.71772 | O40: =O49*O12 -> 75.589491 | P40: =P49*P12 -> 83.148441 | ... R40: =R49*R12 -> 119.96961
C41: Total EBIT | D41: =SUM(D35:D39) -> 584.4 | E41: =SUM(E35:E39) -> 636.9 | F41: =SUM(F35:F39) -> 640.2 | G41: =SUM(G35:G39) -> 657.1 | H41: =SUM(H35:H39) -> 687.7 | I41: =SUM(I35:I40) -> 737.8921 | J41: =SUM(J35:J40) -> 800.23718 | K41: =SUM(K35:K40) -> 865.80316 | L41: =SUM(L35:L40) -> 913.43811 | M41: =SUM(M35:M40) -> 960.93819 | N41: =SUM(N35:N40) -> 995.01442 | O41: =SUM(O35:O40) -> 1052.2432 | P41: =SUM(P35:P40) -> 1084.6689 | ... R41: =SUM(R35:R40) -> 1174.2073
C43: As % of Revenue
C44: =C35 -> Business & Industry | D44: =D35/D7 -> 0.10094128 | E44: =E35/E7 -> 0.081764692 | F44: =F35/F7 -> 0.077175136 | G44: =G35/G7 -> 0.075630666 | H44: =H35/H7 -> 0.076805623 | I44: =I60+I70 -> 0.079 | J44: =J60+J70 -> 0.08 | K44: =K60+K70 -> 0.081 | L44: =L60+L70 -> 0.082 | M44: =M60+M70 -> 0.0825 | N44: =N60+N70 -> 0.0825 | O44: =O60+O70 -> 0.0825 | P44: =P60+P70 -> 0.0825 | ... R44: =R60+R70 -> 0.0825
C45: =C36 -> Manufacturing & Distribution | D45: =D36/D8 -> 0.10515652 | E45: =E36/E8 -> 0.11195682 | F45: =F36/F8 -> 0.10591472 | G45: =G36/G8 -> 0.1069935 | H45: =H36/H8 -> 0.093537625 | I45: =I65+I70 -> 0.095 | J45: =J65+J70 -> 0.0975 | K45: =K65+K70 -> 0.1 | L45: =L65+L70 -> 0.1025 | M45: =M65+M70 -> 0.1025 | N45: =N65+N70 -> 0.1025 | O45: =O65+O70 -> 0.1025 | P45: =P65+P70 -> 0.1025 | ... R45: =R65+R70 -> 0.1025
C46: =C37 -> Education | D46: =D37/D9 -> 0.072333812 | E46: =E37/E9 -> 0.056427459 | F46: =F37/F9 -> 0.056451613 | G46: =G37/G9 -> 0.0611658 | H46: =H37/H9 -> 0.073427332 | I46: 0.08 | J46: 0.085 | K46: 0.09 | L46: 0.09 | M46: 0.09 | N46: 0.09 | O46: 0.09 | P46: 0.09 | Q46: 0.09 | R46: 0.09
C47: =C38 -> Aviation | D47: =D38/D10 -> 0.048594498 | E47: =E38/E10 -> 0.036442786 | F47: =F38/F10 -> 0.064815815 | G47: =G38/G10 -> 0.057234166 | H47: =H38/H10 -> 0.058281934 | I47: 0.055 | J47: 0.055 | K47: 0.055 | L47: 0.055 | M47: 0.055 | N47: 0.055 | O47: 0.055 | P47: 0.055 | Q47: 0.055 | R47: 0.055
...

Sheet DCF
A1: =Input!$A$5 -> Last Edit: | B1: =Input!$B$5 -> 46156
B2: WACC
B3: Cost of Debt | F3: 0.055 | G3: <- ABM's interest rate
B4: Tax Rate | F4: =Model!H29 -> 0.25
B5: Cost of Debt * (1- tax) | F5: =F3*(1-F4) -> 0.04125
B6: Risk Free Rate | F6: 0.0436 | G6: US 10 year yield
B7: Beta | F7: 0.73 | G7: 5Y Beta
B8: Equity Risk Premium | F8: 0.0446 | G8: US Equity Risk Premium Damodaran
B9: Cost of Equity | F9: =(F8*F7+F6) -> 0.076158
B10: D/MV | F10: 0.001
B11: E/MV | F11: =1-F10 -> 0.999
B12: WACC | F12: =F5*F10+F9*F11 -> 0.076123092
B14: Terminal EV/EBITDA | F14: =Comps!O13 -> 13.376607
B15: Terminal Growth Rate | F15: 0.025
B17: =Model!B6 -> In Millions of USD | C17: =Model!C6 -> FY2021 | D17: =Model!D6 -> FY2022 | E17: =Model!E6 -> FY2023 | F17: =Model!F6 -> FY2024 | G17: =Model!G6 -> FY2025 | H17: =Model!H6 -> FY2026 E | I17: =Model!I6 -> FY2027 E | ... Q17: =Model!Q6 -> FY2035 E
B18: Revenue | C18: =Model!C9 -> 6372.8 | D18: =Model!D9 -> 7806.6 | E18: =Model!E9 -> 8096.4 | F18: =Model!F9 -> 8359.4 | G18: =Model!G9 -> 8745.9 | H18: =Model!H9 -> 9287.821 | I18: =Model!I9 -> 9742.0359 | J18: =Model!J9 -> 10178.13 | ... Q18: =Model!Q9 -> 13452.234
B19: Revenue Growth | D19: =D18/C18-1 -> 0.22498745 | E19: =E18/D18-1 -> 0.037122435 | F19: =F18/E18-1 -> 0.032483573 | G19: =G18/F18-1 -> 0.046235376 | H19: =H18/G18-1 -> 0.061962863 | I19: =I18/H18-1 -> 0.048904352 | J19: =J18/I18-1 -> 0.044764218 | K19: =K18/J18-1 -> 0.057542579 | ... Q19: =Q18/P18-1 -> 0.031281151
B20: Segment Operating Expenses | C20: =Model!C10 -> 5788.4 | D20: =Model!D10 -> 7169.7 | E20: =Model!E10 -> 7456.2 | F20: =Model!F10 -> 7702.3 | G20: =Model!G10 -> 8058.2 | H20: =Model!H10 -> 8549.9289 | I20: =Model!I10 -> 8941.7987 | J20: =Model!J10 -> 9312.3273 | ... Q20: =Model!Q10 -> 12278.027
B21: Segment Operating Expenses as a % of Revenue | C21: =C20/C18 -> 0.90829777 | D21: =D20/D18 -> 0.91841519 | E21: =E20/E18 -> 0.92092782 | F21: =F20/F18 -> 0.92139388 | G21: =G20/G18 -> 0.92136887 | H21: =H20/H18 -> 0.92055272 | I21: =I20/I18 -> 0.9178573 | J21: =J20/J18 -> 0.91493495 | ... Q21: =Q20/Q18 -> 0.91271284
B22: Total Segment Operating profit | C22: =C18-C20 -> 584.4 | D22: =D18-D20 -> 636.9 | E22: =E18-E20 -> 640.2 | F22: =F18-F20 -> 657.1 | G22: =G18-G20 -> 687.7 | H22: =H18-H20 -> 737.89209 | I22: =I18-I20 -> 800.23718 | J22: =J18-J20 -> 865.80316 | ... Q22: =Q18-Q20 -> 1174.2073
B23: Margin | C23: =1-C21 -> 0.091702234 | D23: =1-D21 -> 0.081584813 | E23: =1-E21 -> 0.07907218 | F23: =1-F21 -> 0.07860612 | G23: =1-G21 -> 0.07863113 | H23: =1-H21 -> 0.079447278 | I23: =1-I21 -> 0.082142705 | J23: =1-J21 -> 0.085065048 | ... Q23: =1-Q21 -> 0.087287155
B24: EBIT | C24: =Model!C19 -> 209.8 | D24: =Model!D19 -> 352.4 | E24: =Model!E19 -> 409.4 | F24: =Model!F19 -> 213 | G24: =Model!G19 -> 311.8 | H24: =Model!H19 -> 314.59926 | I24: =Model!I19 -> 364.87574 | J24: =Model!J19 -> 418.39794 | ... Q24: =Model!Q19 -> 603.31184
B25: EBIT Margin | C25: =C24/C18 -> 0.032921165 | D25: =D24/D18 -> 0.045141291 | E25: =E24/E18 -> 0.050565684 | F25: =F24/F18 -> 0.025480298 | G25: =G24/G18 -> 0.035650991 | H25: =H24/H18 -> 0.033872235 | I25: =I24/I18 -> 0.037453746 | J25: =J24/J18 -> 0.041107543 | ... Q25: =Q24/Q18 -> 0.044848449
B26: EBITDA | C26: =Model!C34 -> 299.7 | D26: =Model!D34 -> 464.8 | E26: =Model!E34 -> 530.1 | F26: =Model!F34 -> 319.6 | G26: =Model!G34 -> 417.4 | H26: =Model!H34 -> 420.85926 | I26: =Model!I34 -> 468.41148 | J26: =Model!J34 -> 519.36307 | ... Q26: =Model!Q34 -> 717.37286
B27: EBITDA Margin | C27: =C26/C18 -> 0.047027994 | D27: =D26/D18 -> 0.059539364 | E27: =E26/E18 -> 0.065473544 | F27: =F26/F18 -> 0.038232409 | G27: =G26/G18 -> 0.04772522 | H27: =H26/H18 -> 0.045313024 | I27: =I26/I18 -> 0.048081477 | J27: =J26/J18 -> 0.051027355 | ... Q27: =Q26/Q18 -> 0.053327414
B28: Tax | C28: =Model!C26 -> -53.5 | D28: =Model!D26 -> -79.6 | E28: =Model!E26 -> -79.8 | F28: =Model!F26 -> -52.2 | G28: =Model!G26 -> -57.5 | H28: =Model!H26 -> -57.076064 | I28: =Model!I26 -> -68.220852 | J28: =Model!J26 -> -82.694409 | ... Q28: =Model!Q26 -> -134.72135
B29: NOPAT | C29: =C24+C28 -> 156.3 | D29: =D24+D28 -> 272.8 | E29: =E24+E28 -> 329.6 | F29: =F24+F28 -> 160.8 | G29: =G24+G28 -> 254.3 | H29: =H24+H28 -> 257.52319 | I29: =I24+I28 -> 296.65489 | J29: =J24+J28 -> 335.70353 | ... Q29: =Q24+Q28 -> 468.59049
B30: (-) Capex | C30: =Model!C35 -> -34.3 | D30: =Model!D35 -> -50.8 | E30: =Model!E35 -> -52.6 | F30: =Model!F35 -> -59.4 | G30: =Model!G35 -> -79.3 | H30: =Model!H35 -> -65.014747 | I30: =Model!I35 -> -68.194251 | J30: =Model!J35 -> -71.246913 | ... Q30: =Model!Q35 -> -94.165639
B31: (-) Acquisitions | C31: =-Input!F63 -> -710.1 | D31: =-Input!G63 -> -194.6 | E31: =-Input!H63 -> 0 | F31: =-Input!I63 -> -114.3 | G31: =-Input!J63 -> -36.7 | H31: =-Input!K63 -> -264 | I31: =-Input!L63 -> 0 | J31: =-Input!M63 -> 0 | ... Q31: =-Input!T63 -> 0
B32: (+) D&A | C32: =Model!C33 -> 89.9 | D32: =Model!D33 -> 112.4 | E32: =Model!E33 -> 120.7 | F32: =Model!F33 -> 106.6 | G32: =Model!G33 -> 105.6 | H32: =Model!H33 -> 106.26 | I32: =Model!I33 -> 103.53574 | J32: =Model!J33 -> 100.96513 | ... Q32: =Model!Q33 -> 114.06102
B33: (+/-) Changes in NWC | C33: =Model!C36 -> 156.3 | D33: =Model!D36 -> -272.8 | E33: =Model!E36 -> -304.4 | F33: =Model!F36 -> -88.4 | G33: =Model!G36 -> 3.2 | H33: =Model!H36 -> -20.500221 | I33: =Model!I36 -> -68.910983 | J33: =Model!J36 -> -66.454703 | ... Q33: =Model!Q36 -> -61.222997
B34: (-) Changes in Other Assets | C34: 0 | D34: 0 | E34: 0 | F34: 0 | G34: 0 | H34: 0 | I34: 0 | J34: 0 | K34: 0 | L34: 0 | M34: 0 | N34: 0 | O34: 0 | P34: 0 | Q34: 0 | R34: <- Already included in NWC
B35: FCFF | C35: =SUM(C29:C34) -> -341.9 | D35: =SUM(D29:D34) -> -133 | E35: =SUM(E29:E34) -> 93.3 | F35: =SUM(F29:F34) -> 5.3 | G35: =SUM(G29:G34) -> 247.1 | H35: =SUM(H29:H34) -> 14.268224 | I35: =SUM(I29:I34) -> 263.08539 | J35: =SUM(J29:J34) -> 298.96705 | ... Q35: =SUM(Q29:Q34) -> 427.26288
B36: FCFF | H36: =H35 -> 14.268224 | I36: =I35 -> 263.08539 | J36: =J35 -> 298.96705 | K36: =K35 -> 103.22153 | L36: =L35 -> 342.14921 | M36: =M35 -> 357.97615 | N36: =N35 -> 111.28842 | O36: =O35 -> 399.8996 | ... Q36: =Q35 -> 427.26288
B37: FCFF Growth | H37: =H35/G35-1 -> -0.94225729 | I37: =I35/H35-1 -> 17.438553 | J37: =J35/I35-1 -> 0.13638787 | K37: =K35/J35-1 -> -0.65473945 | L37: =L35/K35-1 -> 2.3147078 | M37: =M35/L35-1 -> 0.046257425 | N37: =N35/M35-1 -> -0.68911778 | O37: =O35/N35-1 -> 2.5933622 | ... Q37: =Q35/P35-1 -> 1.114709
B38: FCFF/NOPAT | C38: =C35/C29 -> -2.18746 | D38: =D35/D29 -> -0.48753666 | E38: =E35/E29 -> 0.28307039 | F38: =F35/F29 -> 0.032960199 | G38: =G35/G29 -> 0.97168698 | H38: =H35/H29 -> 0.055405587 | I38: =I35/I29 -> 0.8868399 | J38: =J35/J29 -> 0.89056868 | ... Q38: =Q35/Q29 -> 0.91180441
B39: Capex / Revenue | C39: =C30/-C18 -> 0.0053822496 | D39: =D30/-D18 -> 0.0065073143 | E39: =E30/-E18 -> 0.0064967146 | F39: =F30/-F18 -> 0.0071057731 | G39: =G30/-G18 -> 0.0090671057 | H39: =H30/-H18 -> 0.007 | I39: =I30/-I18 -> 0.007 | J39: =J30/-J18 -> 0.007 | ... Q39: =Q30/-Q18 -> 0.007
B40: PV of FCFF | H40: =H36/(1+$F$12)^Input!K9 -> 13.258914 | I40: =I36/(1+$F$12)^Input!L9 -> 227.18143 | J40: =J36/(1+$F$12)^Input!M9 -> 239.90399 | K40: =K36/(1+$F$12)^Input!N9 -> 76.970177 | L40: =L36/(1+$F$12)^Input!O9 -> 237.08593 | M40: =M36/(1+$F$12)^Input!P9 -> 230.50608 | N40: =N36/(1+$F$12)^Input!Q9 -> 66.59112 | O40: =O36/(1+$F$12)^Input!R9 -> 222.35933 | ... Q40: =Q36/(1+$F$12)^Input!T9 -> 205.15195
B41: Terminal Value (Exit Multiple) | Q41: =Q26*F14 -> 9596.0145
B42: PV of TV (Exit Multiple) | Q42: =Q41/(1+$F$12)^Input!T9 -> 4607.5641
...

Sheet Comps
A1: =[1]Input!$A$5 -> Last Edit: | B1: =[1]Input!$B$5 -> 46152
A2: ="In $M "&B2 -> In $M USD | B2: =[1]Summary!B3 -> USD
B3: Company | C3: Ticker | D3: Currency | E3: Country | F3: Share price | G3: Market Cap | H3: Revenue | I3: Net Income | J3: EV | K3: Revenue Growth (TTM) | L3: EBITDA | M3: EBITDA Margin | N3: EV/Revenue | O3: EV/EBITDA | P3: P/E | Q3: Net Debt / Revenue | R3: Net Debt | S3: Net Debt / EBITDA | T3: FCF Yield
B4: Integrated facilities & support services
B5: Aramark | C5: ARMK-US | D5: USD | E5: USA | F5: 45.779999 | G5: 12370.194 | H5: 18785.762 | I5: 316.936 | J5: 18071.094 | K5: 0.0707 | L5: 1281.226 | M5: =L5/H5 -> 0.068201971 | N5: =J5/H5 -> 0.96195693 | O5: =J5/L5 -> 14.104533 | P5: =G5/I5 -> 39.030574 | Q5: =R5/H5 -> 0.32279995 | R5: 6064.043 | S5: =R5/L5 -> 4.7330003 | T5: 0.0414
B6: Sodexo | C6: SW-FR | D6: USD | E6: FR | F6: 52.06 | G6: 7749.1902 | H6: 27196.647 | I6: 517.07718 | J6: 12023.536 | K6: 0.048 | L6: 1574.2639 | M6: =L6/H6 -> 0.057884485 | N6: =J6/H6 -> 0.44209624 | O6: =J6/L6 -> 7.6375602 | P6: =G6/I6 -> 14.986525 | Q6: =R6/H6 -> 0.18363886 | R6: 4994.3613 | S6: =R6/L6 -> 3.1725057 | T6: 0.0833
B7: ISS | C7: ISS-DK | D7: USD | E7: DK | F7: 41.219276 | G7: 7254.7765 | H7: 12805.675 | I7: 393.61831 | J7: 9232.7312 | K7: 0.054 | L7: 865.56712 | M7: =L7/H7 -> 0.067592461 | N7: =J7/H7 -> 0.72098744 | O7: =J7/L7 -> 10.666684 | P7: =G7/I7 -> 18.430993 | Q7: =R7/H7 -> 0.16390187 | R7: 2098.8742 | S7: =R7/L7 -> 2.4248543 | T7: 0.0906
B8: Cintas | C8: CTAS-US | D8: USD | E8: USA | F8: 169.36 | G8: 68851.609 | H8: 11027.21 | I8: 1930.821 | J8: 71336.396 | K8: 0.087 | L8: 3034.926 | M8: =L8/H8 -> 0.27522157 | N8: =J8/H8 -> 6.4691246 | O8: =J8/L8 -> 23.505152 | P8: =G8/I8 -> 35.65924 | Q8: =R8/H8 -> 0.2480213 | R8: 2734.983 | S8: =R8/L8 -> 0.90116958 | T8: 0.0189
B9: Compass Group | C9: CPG-GB | D9: USD | E9: UK | F9: 29.77 | G9: 50912.332 | H9: 46070 | I9: 1868 | J9: 56729.332 | K9: 0.097 | L9: 4485 | M9: =L9/H9 -> 0.097351856 | N9: =J9/H9 -> 1.2313725 | O9: =J9/L9 -> 12.648681 | P9: =G9/I9 -> 27.254996 | Q9: =R9/H9 -> 0.13928804 | R9: 6417 | S9: =R9/L9 -> 1.4307692 | T9: -
B10: Rentokil Initial | C10: RTO-GB | D10: USD | E10: UK | F10: 6.804471 | G10: 17300.823 | H10: 6908.0001 | I10: 470.00001 | J10: 22445.717 | K10: -0.005 | L10: 1474 | M10: =L10/H10 -> 0.2133758 | N10: =J10/H10 -> 3.2492352 | O10: =J10/L10 -> 15.227759 | P10: =G10/I10 -> 36.810261 | Q10: =R10/H10 -> 0.55138967 | R10: 3808.9999 | S10: =R10/L10 -> 2.5841247 | T10: 0.0514
B11: =[1]Input!B1 -> ABM Industries Inc | C11: =[1]Summary!B2 -> ABM | D11: =[1]Summary!B3 -> USD | E11: USA | F11: 40.639999 | G11: 2468.1818 | H11: 8874.5 | I11: 157.6 | J11: 4004.7818 | K11: 0.056 | L11: 496.6 | M11: =L11/H11 -> 0.055958082 | N11: =J11/H11 -> 0.45126844 | O11: =J11/L11 -> 8.0644015 | P11: =G11/I11 -> 15.661052 | Q11: =R11/H11 -> 0.18459632 | R11: 1638.2 | S11: =R11/L11 -> 3.2988321 | T11: 0.0575
B12: 25th percentile | G12: =PERCENTILE(G5:G10, 0.25) -> 8904.4411 | J12: =PERCENTILE(J5:J10, 0.25) -> 13535.425 | K12: =PERCENTILE(K5:K10, 0.25) -> 0.0495 | L12: =PERCENTILE(L5:L10, 0.25) -> 1329.4195 | M12: =PERCENTILE(M5:M10, 0.25) -> 0.067744839 | N12: =PERCENTILE(N5:N10, 0.25) -> 0.78122981 | O12: =PERCENTILE(O5:O10, 0.25) -> 11.162183 | P12: =PERCENTILE(P5:P10, 0.25) -> 20.636994 | Q12: =PERCENTILE(Q5:Q10, 0.25) -> 0.16883612 | ... T12: =PERCENTILE(T5:T10, 0.25) -> 0.0414
B13: Median | G13: =MEDIAN(G5:G10) -> 14835.508 | J13: =MEDIAN(J5:J10) -> 20258.405 | K13: =MEDIAN(K5:K10) -> 0.06235 | L13: =MEDIAN(L5:L10) -> 1524.132 | M13: =MEDIAN(M5:M10) -> 0.082776914 | N13: =MEDIAN(N5:N10) -> 1.0966647 | O13: =MEDIAN(O5:O10) -> 13.376607 | P13: =MEDIAN(P5:P10) -> 31.457118 | Q13: =MEDIAN(Q5:Q10) -> 0.21583008 | ... T13: =MEDIAN(T5:T10) -> 0.0514
B14: Mean | G14: =AVERAGE(G5:G10) -> 27406.487 | J14: =AVERAGE(J5:J10) -> 31639.801 | K14: =AVERAGE(K5:K10) -> 0.058616667 | L14: =AVERAGE(L5:L10) -> 2119.1638 | M14: =AVERAGE(M5:M10) -> 0.12993802 | N14: =AVERAGE(N5:N10) -> 2.1791288 | O14: =AVERAGE(O5:O10) -> 13.965061 | P14: =AVERAGE(P5:P10) -> 28.695431 | Q14: =AVERAGE(Q5:Q10) -> 0.26817328 | ... T14: =AVERAGE(T5:T10) -> 0.05712
B16: Integrated facilities & support services
B17: Rollins | C17: ROL-US | D17: USD | E17: USA | F17: 54.189999 | G17: 26090.516 | H17: 3844.97 | I17: 857.3 | J17: 26624.526 | K17: 0.11 | L17: 865.57 | M17: =L17/H17 -> 0.22511749 | N17: =J17/H17 -> 6.9245081 | O17: =J17/L17 -> 30.759529 | P17: =G17/I17 -> 30.433356 | Q17: =R17/H17 -> 0.2472321 | R17: 950.6 | S17: =R17/L17 -> 1.0982358 | T17: 0.0224
B18: Ecolab | C18: ECL-US | D18: USD | E18: USA | F18: 263.42001 | G18: 75044.202 | H18: 16081.2 | I18: 2075.6 | J18: 82973.002 | K18: 0.022 | L18: 3874.3 | M18: =L18/H18 -> 0.24092108 | N18: =J18/H18 -> 5.1596275 | O18: =J18/L18 -> 21.416256 | P18: =G18/I18 -> 36.155426 | Q18: =R18/H18 -> 0.5193207 | R18: 8351.3 | S18: =R18/L18 -> 2.1555636 | T18: 0.0254
B19: EMCOR Group | C19: EME-US | D19: USD | E19: USA | F19: 943.75 | G19: 42088.702 | H19: 17747.283 | I19: 1337.6 | J19: 41173.319 | K19: 0.183 | L19: 1850.68 | M19: =L19/H19 -> 0.10427962 | N19: =J19/H19 -> 2.3199787 | O19: =J19/L19 -> 22.247671 | P19: =G19/I19 -> 31.465836 | Q19: =R19/H19 -> -0.022538661 | R19: -400 | S19: =R19/L19 -> -0.21613677 | T19: 0.0431
B20: Comfort Systems USA | C20: FIX-US | D20: USD | E20: USA | F20: 2011.49 | G20: 70931.393 | H20: 10135.687 | I20: 1223.6 | J20: 69855.508 | K20: 0.384 | L20: 1736.283 | M20: =L20/H20 -> 0.17130393 | N20: =J20/H20 -> 6.8920349 | O20: =J20/L20 -> 40.232789 | P20: =G20/I20 -> 57.969429 | Q20: =R20/H20 -> -0.072614713 | R20: -736 | S20: =R20/L20 -> -0.42389403 | T20: 0.0311
B21: CBRE Group A | C21: CBRE-US | D21: USD | E21: USA | F21: 145.16 | G21: 43172.352 | H21: 42168 | I21: 1312 | J21: 49281.352 | K21: 0.148 | L21: 1962 | M21: =L21/H21 -> 0.046528173 | N21: =J21/H21 -> 1.1686908 | O21: =J21/L21 -> 25.117916 | P21: =G21/I21 -> 32.905756 | Q21: =R21/H21 -> 0.056725479 | R21: 2392 | S21: =R21/L21 -> 1.2191641 | T21: 0.0247
B22: Jones Lang LaSalle | C22: JLL-US | D22: USD | E22: USA | F22: 325.51999 | G22: 15568.487 | H22: 26755.7 | I22: 896 | J22: 17371.187 | K22: 0.112 | L22: 1482.5 | M22: =L22/H22 -> 0.055408754 | N22: =J22/H22 -> 0.64925182 | O22: =J22/L22 -> 11.717495 | P22: =G22/I22 -> 17.375543 | Q22: =R22/H22 -> 0.12965462 | R22: 3469 | S22: =R22/L22 -> 2.3399663 | T22: 0.0634
B23: Brink's | C23: BCO-US | D23: USD | E23: USA | F23: 109.01 | G23: 4577.6519 | H23: 5389.6 | I23: 180 | J23: 6885.3519 | K23: 0.073 | L23: 875.6 | M23: =L23/H23 -> 0.16246104 | N23: =J23/H23 -> 1.2775256 | O23: =J23/L23 -> 7.8635814 | P23: =G23/I23 -> 25.431399 | Q23: =R23/H23 -> 0.43992133 | R23: 2371 | S23: =R23/L23 -> 2.7078575 | T23: 0.088
B24: =B11 -> ABM Industries Inc | C24: ABM | D24: USD | E24: USA | F24: 40.639999 | G24: 2468.1818 | H24: 8874.5 | I24: 157.6 | J24: 4004.7818 | K24: 0.056 | L24: 496.6 | M24: =L24/H24 -> 0.055958082 | N24: =J24/H24 -> 0.45126844 | O24: =J24/L24 -> 8.0644015 | P24: =G24/I24 -> 15.661052 | Q24: =R24/H24 -> 0.18459632 | R24: 1638.2 | S24: 3.7859949 | T24: 0.0575
B25: Median | G25: =MEDIAN(G17:G23) -> 42088.702 | J25: =MEDIAN(J17:J23) -> 41173.319 | K25: =MEDIAN(K17:K23) -> 0.112 | L25: =MEDIAN(L17:L23) -> 1736.283 | M25: =MEDIAN(M17:M23) -> 0.16246104 | N25: =MEDIAN(N17:N23) -> 2.3199787 | O25: =MEDIAN(O17:O23) -> 22.247671 | P25: =MEDIAN(P17:P23) -> 31.465836 | Q25: =MEDIAN(Q17:Q23) -> 0.12965462 | ... T25: =MEDIAN(T17:T23) -> 0.0311
B26: Mean | G26: =AVERAGE(G17:G23) -> 39639.043 | J26: =AVERAGE(J17:J23) -> 42023.464 | K26: =AVERAGE(K17:K23) -> 0.14742857 | L26: =AVERAGE(L17:L23) -> 1806.7047 | M26: =AVERAGE(M17:M23) -> 0.14371715 | N26: =AVERAGE(N17:N23) -> 3.4845168 | O26: =AVERAGE(O17:O23) -> 22.765034 | P26: =AVERAGE(P17:P23) -> 33.105249 | Q26: =AVERAGE(Q17:Q23) -> 0.18538584 | ... T26: =AVERAGE(T17:T23) -> 0.042585714
B32: Comps Valuation | K32: Weight | L32: Method | M32: TP | N32: Blended TP
K33: =(1-K34)/2 -> 0.2 | L33: Revenue | M33: =E41 -> 88.034991 | N33: =M33*K33+M34*K34+M35*K35 -> 67.158528
B34: EV/Revenue | C34: EV/ Revenue | E34: =CHOOSE(Segments!I54,N13,N12,N11) -> 0.78122981 | G34: Median | K34: 0.6 | L34: EBITDA | M34: =E50 -> 65.137401
C35: Revenue | E35: =H11 -> 8874.5 | K35: =1-K33-K34 -> 0.2 | L35: P/E | M35: =E55 -> 52.345449
C36: EV | E36: =E35*E34 -> 6933.024
C37: Less: Debt | D37: =[1]Model!H177 -> 0 | E37: =[1]DCF!$C$67 -> 1693.4
C38: Plus: Cash | D38: =[1]Model!H43 -> 1.597091 | E38: =[1]DCF!$C$69 -> 104.1
C39: Equity Value | E39: =E36-E37+E38 -> 5343.724
C40: Fwd S/O | E40: =[1]DCF!$H$50 -> 60.7
C41: Price | E41: =E39/E40 -> 88.034991
B43: EV/EBITDA | C43: EV/ EBITDA | E43: =CHOOSE(Segments!I54,O13,O12,O11) -> 11.162183 | G43: Median
C44: EBITDA | E44: =L24 -> 496.6
C45: EV | E45: =E44*E43 -> 5543.1402
C46: =[1]DCF!B57 -> Less: Debt | E46: =[1]DCF!$C$67 -> 1693.4
C47: =[1]DCF!B59 -> Plus: Cash | E47: =[1]DCF!$C$69 -> 104.1
...

Sheet ASSUMPTIONS >>>

Sheet Acquisition related
B3: in MMs of USD | E3: FY2026 E | F3: FY2027 E | G3: FY2028 E | H3: FY2029 E | I3: FY2030 E | J3: FY2031 E | K3: FY2032 E | L3: FY2033 E | M3: FY2034 E | N3: FY2035 E
B4: Acquisitions
B5: Cost | E5: 264 | H5: 200 | K5: 250 | M5: 200
B6: Debt used | E6: 255 | F6: =F5 -> 0 | G6: =G5 -> 0 | H6: =H5 -> 200 | I6: =I5 -> 0 | J6: =J5 -> 0 | K6: =K5 -> 250 | L6: =L5 -> 0 | M6: =M5 -> 200 | N6: =N5 -> 0
B7: Cash used | E7: =E5-E6 -> 9 | F7: =F5-F6 -> 0 | G7: =G5-G6 -> 0 | H7: =H5-H6 -> 0 | I7: =I5-I6 -> 0 | J7: =J5-J6 -> 0 | K7: =K5-K6 -> 0 | L7: =L5-L6 -> 0 | ... N7: =N5-N6 -> 0
B9: Revenue multiple | H9: 0.8 | K9: 0.8 | M9: 0.8
B10: Revenue contribution | E10: 125 | F10: =F9*F5 -> 0 | G10: =G9*G5 -> 0 | H10: =H9*H5 -> 160 | I10: =I9*I5 -> 0 | J10: =J9*J5 -> 0 | K10: =K9*K5 -> 200 | L10: =L9*L5 -> 0 | M10: =M9*M5 -> 160 | N10: =N9*N5 -> 0
B14: Previous acquisitions | D14: Purchase price | E14: Revenue | F14: Revenue/Price | H14: Other assumptions:
B15: Able services (2021) | D15: 742 | E15: 1100 | F15: =E15/D15 -> 1.4824798 | H15: - 20% of acquisition allocated to intantgibles
B16: Ravenvolt (2022) | D16: 170 | E16: 72.3 | F16: =E16/D16 -> 0.42529412 | H16: - Rest allocated to goodwill
B17: Momentum Support (2022) | D17: 55 | E17: 32 | F17: =E17/D17 -> 0.58181818 | H17: - All of acquisition costs financed through debt
B18: Quality uptime (2024) | D18: 118 | E18: 78 | F18: =E18/D18 -> 0.66101695 | H18: - The debt is amortized at 5% p.a.
B19: LMC FM Limited (2025) | D19: 23 | E19: 55 | F19: =E19/D19 -> 2.3913043 | H19: - All of the revenue from acquired companies has a growth rate of 15%, moderating in last 5 years
B20: WGNSTAR (2026) | D20: 264 | E20: 175 | F20: =E20/D20 -> 0.66287879 | H20: - EBIT margin assumed at 11%, since acquisition's EBIT normally 100-200 bps above segment's, and acquisitions are focused on ATS and M&D segments
B21: Avg | F21: =AVERAGE(F15:F20) -> 1.034132
B22: Median | F22: =MEDIAN(F15:F20) -> 0.66194787

Sheet Thesis 1
B3: Bull | E3: FY2025 | F3: FY2026 E | G3: FY2027 E | H3: FY2028 E | I3: FY2029 E | J3: FY2030 E | K3: FY2031 E | L3: FY2032 E | M3: FY2033 E | N3: FY2034 E | O3: FY2035 E
B4: Thesis 1 - technical segments
B5: Technical solutions
B6: Revenue growth | E6: =Segments!$H$21 -> 0.18709837 | F6: 0.18 | G6: 0.17 | H6: 0.16 | I6: 0.15 | J6: 0.14 | K6: 0.12 | L6: 0.1 | M6: 0.1 | N6: 0.09 | O6: 0.08
B7: Target size for revenue as % of Total | E7: =Segments!$H$30 -> 0.10983432 | O7: 0.24 | P7: <- Target
B8: Implied revenue based on revenue growth | E8: =Segments!$H$11 -> 960.6 | F8: =(1+F6)*E8 -> 1133.508 | G8: =(1+G6)*F8 -> 1326.2044 | H8: =(1+H6)*G8 -> 1538.3971 | I8: =(1+I6)*H8 -> 1769.1566 | J8: =(1+J6)*I8 -> 2016.8385 | K8: =(1+K6)*J8 -> 2258.8592 | L8: =(1+L6)*K8 -> 2484.7451 | M8: =(1+M6)*L8 -> 2733.2196 | ... O8: =(1+O6)*N8 -> 3217.5461
B9: Implied % of total revenue | E9: =E8/(SUM(Segments!H$7:'Segments'!H$10)+E8) -> 0.10983432 | F9: =F8/(SUM(Segments!I$7:'Segments'!I$10)+F8) -> 0.12370732 | G9: =G8/(SUM(Segments!J$7:'Segments'!J$10)+G8) -> 0.13800798 | H9: =H8/(SUM(Segments!K$7:'Segments'!K$10)+H8) -> 0.15303986 | I9: =I8/(SUM(Segments!L$7:'Segments'!L$10)+I8) -> 0.16842649 | J9: =J8/(SUM(Segments!M$7:'Segments'!M$10)+J8) -> 0.1842853 | K9: =K8/(SUM(Segments!N$7:'Segments'!N$10)+K8) -> 0.19841258 | L9: =L8/(SUM(Segments!O$7:'Segments'!O$10)+L8) -> 0.21057923 | ... O9: =O8/(SUM(Segments!R$7:'Segments'!R$10)+O8) -> 0.247243
B11: Base
B12: Thesis 1 - technical segments
B13: Technical solutions
B14: Revenue growth | E14: =Segments!$H$21 -> 0.18709837 | F14: 0.18 | G14: 0.16 | H14: 0.14 | I14: 0.12 | J14: 0.1 | K14: 0.08 | L14: 0.08 | M14: 0.06 | N14: 0.06 | O14: 0.06
B15: Target size for revenue as % of Total | E15: =Segments!$H$30 -> 0.10983432 | O15: 0.2 | P15: <- Target
